<?xml version="1.0" encoding="utf-8"?>
<!-- =================================================================================== -->
<!-- |    This document was autogenerated by xacro from strirus_gamma.xacro            | -->
<!-- |    EDITING THIS FILE BY HAND IS NOT RECOMMENDED                                 | -->
<!-- =================================================================================== -->
<robot name="strirus_gamma" xmlns:xacro="http://www.ros.org/wiki/xacro">
  <mujoco>
    <!-- if it doesn't work, try this and put the value by your own
		$(find strirus_cad_design)/stl/collision-->
    <compiler balanceinertia="true" convexhull="false" fusestatic="false" inertiafromgeom="false" meshdir="../../../../strirus_cad_design/stl/collision/"/>
  </mujoco>
  <gazebo>
    <self_collide>1</self_collide>
  </gazebo>
  <!-- 	<xacro:arg name="namespace" default="/"/>
        <xacro:property name="namespace" value="$(arg namespace)" /> -->
  <!-- Constants for simulating -->
  <!-- Xacro arg provides xacro.py file.xacro real_number_of_legs:=12 -->
  <!-- Import Rviz colors -->
  <material name="black">
    <color rgba="0.0 0.0 0.0 1.0"/>
  </material>
  <material name="blue">
    <color rgba="0.0 0.0 0.8 1.0"/>
  </material>
  <material name="green">
    <color rgba="0.0 0.8 0.0 1.0"/>
  </material>
  <material name="grey">
    <color rgba="0.2 0.2 0.2 1.0"/>
  </material>
  <material name="orange">
    <color rgba="1.0 0.423529411765 0.0392156862745 1.0"/>
  </material>
  <material name="brown">
    <color rgba="0.870588235294 0.811764705882 0.764705882353 1.0"/>
  </material>
  <material name="red">
    <color rgba="0.8 0.0 0.0 1.0"/>
  </material>
  <material name="white">
    <color rgba="1.0 1.0 1.0 1.0"/>
  </material>
  <!-- Body description -->
  <link name="base_footprint"/>
  <joint name="base_footprint_body_1_part_fixed" type="fixed">
    <parent link="base_footprint"/>
    <child link="body_1_part"/>
    <origin rpy="0  0  0" xyz="0 0 0.07"/>
  </joint>
  <link name="tof_camera_2"/>
  <joint name="body_2_part_tof_camera_2_fixed" type="fixed">
    <parent link="body_2_part"/>
    <child link="tof_camera_2"/>
    <origin rpy="0  0  0" xyz="-0.2845 0 0"/>
  </joint>
  <!-- omni_deg in DEG!! not  in rad -->
  <!--body 1 part -->
  <link name="body_1_part">
    <inertial>
      <mass value="2.388930632"/>
      <origin rpy="0  0  0" xyz="0.097941980 -0.000003641 -0.002393165"/>
      <inertia ixx="0.021308871" ixy="-0.000001095" ixz="0.000148655" iyy="0.016353233" iyz="0.000000225" izz="0.036670475"/>
    </inertial>
    <collision>
      <origin rpy="0  0  0" xyz="0 0 0"/>
      <geometry>
        <mesh filename="package://strirus_cad_design/stl/collision/body_1_15_part.stl" scale="1 1 1"/>
      </geometry>
    </collision>
    <visual>
      <origin rpy="0  0  0" xyz="0 0 0"/>
      <geometry>
        <mesh filename="package://strirus_cad_design/stl/visual/body_1_15_part.stl" scale="1 1 1"/>
      </geometry>
      <material name="white"/>
    </visual>
  </link>
  <link name="tof_camera_1"/>
  <joint name="body_1_part_tof_camera_1_fixed" type="fixed">
    <parent link="body_1_part"/>
    <child link="tof_camera_1"/>
    <origin rpy="0  0  0" xyz="-0.0375 0 0"/>
  </joint>
  <!--body 2 part -->
  <link name="body_2_part">
    <inertial>
      <mass value="2.355831379"/>
      <origin rpy="0  0  0" xyz="0.149047442 0.000005747 -0.002719841"/>
      <inertia ixx="0.021283571" ixy="-0.000001623" ixz="-0.000148653" iyy="0.016318351" iyz=" -0.000000091" izz="0.036647243"/>
    </inertial>
    <collision>
      <origin rpy="0  0  0" xyz="0 0 0"/>
      <geometry>
        <mesh filename="package://strirus_cad_design/stl/collision/body_2_15_part.stl" scale="1 1 1"/>
      </geometry>
    </collision>
    <visual>
      <origin rpy="0  0  0" xyz="0 0 0"/>
      <geometry>
        <mesh filename="package://strirus_cad_design/stl/visual/body_2_15_part.stl" scale="1 1 1"/>
      </geometry>
      <material name="orange"/>
    </visual>
  </link>
  <!-- bridge part -->
  <!-- brdige 1 part -->
  <link name="bridge_1_part">
    <inertial>
      <mass value="0.093452612"/>
      <origin rpy="0  0  0" xyz="0.006688724 0.000000000 0.000077504"/>
      <inertia ixx="0.000234667" ixy="0.000000000" ixz="0.000000048" iyy="0.000029584" iyz="0.000000000" izz="0.000231388"/>
    </inertial>
    <collision>
      <origin rpy="0  0  0" xyz="0 0 0"/>
      <geometry>
        <mesh filename="package://strirus_cad_design/stl/collision/bridge_1_part.stl" scale="1 1 1"/>
      </geometry>
    </collision>
    <visual>
      <origin rpy="0  0  0" xyz="0 0 0"/>
      <geometry>
        <mesh filename="package://strirus_cad_design/stl/visual/bridge_1_part.stl" scale="1 1 1"/>
      </geometry>
      <material name="white"/>
    </visual>
  </link>
  <!-- brdige 2 part -->
  <link name="bridge_2_part">
    <inertial>
      <mass value="0.093452612"/>
      <origin rpy="0  0  0" xyz="0.023311276 0.000000000 0.000077504"/>
      <inertia ixx="0.000215112" ixy="0.000000000" ixz="0.000000048" iyy="0.000029584" iyz="0.000000000" izz="0.000211832"/>
    </inertial>
    <collision>
      <origin rpy="0  0  0" xyz="-0 0 0"/>
      <geometry>
        <mesh filename="package://strirus_cad_design/stl/collision/bridge_2_part.stl" scale="1 1 1"/>
      </geometry>
    </collision>
    <visual>
      <origin rpy="0  0  0" xyz="-0 0 0"/>
      <geometry>
        <mesh filename="package://strirus_cad_design/stl/visual/bridge_2_part.stl" scale="1 1 1"/>
      </geometry>
      <material name="orange"/>
    </visual>
  </link>
  <joint name="segment_up_revolute" type="revolute">
    <parent link="bridge_1_part"/>
    <child link="bridge_2_part"/>
    <origin rpy="0 -0.0 0" xyz="0.03 0 0"/>
    <axis xyz="0 -1  0"/>
    <limit effort="5" lower="-1.308996939" upper="1.308996939" velocity="0.5"/>
    <joint_properties damping="0.0" friction="0.0"/>
  </joint>
  <joint name="segment_side_revolute" type="revolute">
    <parent link="body_1_part"/>
    <child link="bridge_1_part"/>
    <origin rpy="0 0 -0.0" xyz="0.247 0 0"/>
    <axis xyz="0 0  -1"/>
    <limit effort="5" lower="-0.261799387799" upper="0.261799387799" velocity="0.5"/>
    <joint_properties damping="0.0" friction="0.0"/>
  </joint>
  <joint name="bridge_2_part_body_2_part_fixed" type="fixed">
    <parent link="bridge_2_part"/>
    <child link="body_2_part"/>
    <origin rpy="0 0 0" xyz="0.03 0 0"/>
  </joint>
  <link name="leg_left_5">
    <inertial>
      <mass value="0.012706347"/>
      <origin rpy="0 0 0" xyz="-0.013348671 0 -0.027584119"/>
      <inertia ixx="0.000007895" ixy="0" ixz="0.000001300" iyy="0.000009763" iyz="0" izz="0.000002004"/>
    </inertial>
    <collision>
      <origin rpy="0  0  0" xyz="0 0 0"/>
      <geometry>
        <mesh filename="package://strirus_cad_design/stl/collision/leg_70.stl" scale="1 1 1"/>
      </geometry>
    </collision>
    <visual>
      <origin rpy="0  0  0" xyz="0 0 0"/>
      <geometry>
        <mesh filename="package://strirus_cad_design/stl/visual/leg_70.stl" scale="1 1 1"/>
      </geometry>
      <material name="white"/>
    </visual>
  </link>
  <joint name="leg_left_5_revolute_joint" type="revolute">
    <child link="leg_left_5"/>
    <parent link="body_2_part"/>
    <origin rpy="0       10.471975512        -0.261799387799" xyz="0.042893980876 0.1594607377  0"/>
    <axis xyz="0 -1  0"/>
    <limit effort="1.5" lower="-1e+5" upper="1e+5" velocity="3.0"/>
    <joint_properties damping="0.0" friction="0.0"/>
  </joint>
  <gazebo reference="leg_left_5">
    <material>Gazebo/Gray</material>
  </gazebo>
  <link name="leg_left_4">
    <inertial>
      <mass value="0.012706347"/>
      <origin rpy="0 0 0" xyz="-0.013348671 0 -0.027584119"/>
      <inertia ixx="0.000007895" ixy="0" ixz="0.000001300" iyy="0.000009763" iyz="0" izz="0.000002004"/>
    </inertial>
    <collision>
      <origin rpy="0  0  0" xyz="0 0 0"/>
      <geometry>
        <mesh filename="package://strirus_cad_design/stl/collision/leg_70.stl" scale="1 1 1"/>
      </geometry>
    </collision>
    <visual>
      <origin rpy="0  0  0" xyz="0 0 0"/>
      <geometry>
        <mesh filename="package://strirus_cad_design/stl/visual/leg_70.stl" scale="1 1 1"/>
      </geometry>
      <material name="white"/>
    </visual>
  </link>
  <joint name="leg_left_4_revolute_joint" type="revolute">
    <child link="leg_left_4"/>
    <parent link="body_2_part"/>
    <origin rpy="0       8.37758040957        -0.261799387799" xyz="0.148893980876 0.1594607377  0"/>
    <axis xyz="0 -1  0"/>
    <limit effort="1.5" lower="-1e+5" upper="1e+5" velocity="3.0"/>
    <joint_properties damping="0.0" friction="0.0"/>
  </joint>
  <gazebo reference="leg_left_4">
    <material>Gazebo/Gray</material>
  </gazebo>
  <link name="leg_left_3">
    <inertial>
      <mass value="0.012706347"/>
      <origin rpy="0 0 0" xyz="-0.013348671 0 -0.027584119"/>
      <inertia ixx="0.000007895" ixy="0" ixz="0.000001300" iyy="0.000009763" iyz="0" izz="0.000002004"/>
    </inertial>
    <collision>
      <origin rpy="0  0  0" xyz="0 0 0"/>
      <geometry>
        <mesh filename="package://strirus_cad_design/stl/collision/leg_70.stl" scale="1 1 1"/>
      </geometry>
    </collision>
    <visual>
      <origin rpy="0  0  0" xyz="0 0 0"/>
      <geometry>
        <mesh filename="package://strirus_cad_design/stl/visual/leg_70.stl" scale="1 1 1"/>
      </geometry>
      <material name="white"/>
    </visual>
  </link>
  <joint name="leg_left_3_revolute_joint" type="revolute">
    <child link="leg_left_3"/>
    <parent link="body_2_part"/>
    <origin rpy="0       6.28318530718        -0.261799387799" xyz="0.254893980876 0.1594607377  0"/>
    <axis xyz="0 -1  0"/>
    <limit effort="1.5" lower="-1e+5" upper="1e+5" velocity="3.0"/>
    <joint_properties damping="0.0" friction="0.0"/>
  </joint>
  <gazebo reference="leg_left_3">
    <material>Gazebo/Gray</material>
  </gazebo>
  <link name="leg_left_2">
    <inertial>
      <mass value="0.012706347"/>
      <origin rpy="0 0 0" xyz="-0.013348671 0 -0.027584119"/>
      <inertia ixx="0.000007895" ixy="0" ixz="0.000001300" iyy="0.000009763" iyz="0" izz="0.000002004"/>
    </inertial>
    <collision>
      <origin rpy="0  0  0" xyz="0 0 0"/>
      <geometry>
        <mesh filename="package://strirus_cad_design/stl/collision/leg_70.stl" scale="1 1 1"/>
      </geometry>
    </collision>
    <visual>
      <origin rpy="0  0  0" xyz="0 0 0"/>
      <geometry>
        <mesh filename="package://strirus_cad_design/stl/visual/leg_70.stl" scale="1 1 1"/>
      </geometry>
      <material name="white"/>
    </visual>
  </link>
  <joint name="leg_left_2_revolute_joint" type="revolute">
    <child link="leg_left_2"/>
    <parent link="body_1_part"/>
    <origin rpy="0       4.18879020479        0.261799387799" xyz="0.204106019124 0.1594607377  0"/>
    <axis xyz="0 -1  0"/>
    <limit effort="1.5" lower="-1e+5" upper="1e+5" velocity="3.0"/>
    <joint_properties damping="0.0" friction="0.0"/>
  </joint>
  <gazebo reference="leg_left_2">
    <material>Gazebo/Gray</material>
  </gazebo>
  <link name="leg_left_1">
    <inertial>
      <mass value="0.012706347"/>
      <origin rpy="0 0 0" xyz="-0.013348671 0 -0.027584119"/>
      <inertia ixx="0.000007895" ixy="0" ixz="0.000001300" iyy="0.000009763" iyz="0" izz="0.000002004"/>
    </inertial>
    <collision>
      <origin rpy="0  0  0" xyz="0 0 0"/>
      <geometry>
        <mesh filename="package://strirus_cad_design/stl/collision/leg_70.stl" scale="1 1 1"/>
      </geometry>
    </collision>
    <visual>
      <origin rpy="0  0  0" xyz="0 0 0"/>
      <geometry>
        <mesh filename="package://strirus_cad_design/stl/visual/leg_70.stl" scale="1 1 1"/>
      </geometry>
      <material name="white"/>
    </visual>
  </link>
  <joint name="leg_left_1_revolute_joint" type="revolute">
    <child link="leg_left_1"/>
    <parent link="body_1_part"/>
    <origin rpy="0       2.09439510239        0.261799387799" xyz="0.098106019124 0.1594607377  0"/>
    <axis xyz="0 -1  0"/>
    <limit effort="1.5" lower="-1e+5" upper="1e+5" velocity="3.0"/>
    <joint_properties damping="0.0" friction="0.0"/>
  </joint>
  <gazebo reference="leg_left_1">
    <material>Gazebo/Gray</material>
  </gazebo>
  <link name="leg_left_0">
    <inertial>
      <mass value="0.012706347"/>
      <origin rpy="0 0 0" xyz="-0.013348671 0 -0.027584119"/>
      <inertia ixx="0.000007895" ixy="0" ixz="0.000001300" iyy="0.000009763" iyz="0" izz="0.000002004"/>
    </inertial>
    <collision>
      <origin rpy="0  0  0" xyz="0 0 0"/>
      <geometry>
        <mesh filename="package://strirus_cad_design/stl/collision/leg_70.stl" scale="1 1 1"/>
      </geometry>
    </collision>
    <visual>
      <origin rpy="0  0  0" xyz="0 0 0"/>
      <geometry>
        <mesh filename="package://strirus_cad_design/stl/visual/leg_70.stl" scale="1 1 1"/>
      </geometry>
      <material name="white"/>
    </visual>
  </link>
  <joint name="leg_left_0_revolute_joint" type="revolute">
    <child link="leg_left_0"/>
    <parent link="body_1_part"/>
    <origin rpy="0       0.0        0.261799387799" xyz="-0.007893980876 0.1594607377  0"/>
    <axis xyz="0 -1  0"/>
    <limit effort="1.5" lower="-1e+5" upper="1e+5" velocity="3.0"/>
    <joint_properties damping="0.0" friction="0.0"/>
  </joint>
  <gazebo reference="leg_left_0">
    <material>Gazebo/Gray</material>
  </gazebo>
  <link name="leg_right_5">
    <inertial>
      <mass value="0.012706347"/>
      <origin rpy="0 0 0" xyz="-0.013348671 0 -0.027584119"/>
      <inertia ixx="0.000007895" ixy="0" ixz="0.000001300" iyy="0.000009763" iyz="0" izz="0.000002004"/>
    </inertial>
    <collision>
      <origin rpy="0  0  0" xyz="0 0 0"/>
      <geometry>
        <mesh filename="package://strirus_cad_design/stl/collision/leg_70.stl" scale="1 1 1"/>
      </geometry>
    </collision>
    <visual>
      <origin rpy="0  0  0" xyz="0 0 0"/>
      <geometry>
        <mesh filename="package://strirus_cad_design/stl/visual/leg_70.stl" scale="1 1 1"/>
      </geometry>
      <material name="white"/>
    </visual>
  </link>
  <joint name="leg_right_5_revolute_joint" type="revolute">
    <child link="leg_right_5"/>
    <parent link="body_2_part"/>
    <origin rpy="0       10.471975512        0.261799387799" xyz="0.042893980876 -0.1594607377  0"/>
    <axis xyz="0 -1  0"/>
    <limit effort="1.5" lower="-1e+5" upper="1e+5" velocity="3.0"/>
    <joint_properties damping="0.0" friction="0.0"/>
  </joint>
  <gazebo reference="leg_right_5">
    <material>Gazebo/Gray</material>
  </gazebo>
  <link name="leg_right_4">
    <inertial>
      <mass value="0.012706347"/>
      <origin rpy="0 0 0" xyz="-0.013348671 0 -0.027584119"/>
      <inertia ixx="0.000007895" ixy="0" ixz="0.000001300" iyy="0.000009763" iyz="0" izz="0.000002004"/>
    </inertial>
    <collision>
      <origin rpy="0  0  0" xyz="0 0 0"/>
      <geometry>
        <mesh filename="package://strirus_cad_design/stl/collision/leg_70.stl" scale="1 1 1"/>
      </geometry>
    </collision>
    <visual>
      <origin rpy="0  0  0" xyz="0 0 0"/>
      <geometry>
        <mesh filename="package://strirus_cad_design/stl/visual/leg_70.stl" scale="1 1 1"/>
      </geometry>
      <material name="white"/>
    </visual>
  </link>
  <joint name="leg_right_4_revolute_joint" type="revolute">
    <child link="leg_right_4"/>
    <parent link="body_2_part"/>
    <origin rpy="0       8.37758040957        0.261799387799" xyz="0.148893980876 -0.1594607377  0"/>
    <axis xyz="0 -1  0"/>
    <limit effort="1.5" lower="-1e+5" upper="1e+5" velocity="3.0"/>
    <joint_properties damping="0.0" friction="0.0"/>
  </joint>
  <gazebo reference="leg_right_4">
    <material>Gazebo/Gray</material>
  </gazebo>
  <link name="leg_right_3">
    <inertial>
      <mass value="0.012706347"/>
      <origin rpy="0 0 0" xyz="-0.013348671 0 -0.027584119"/>
      <inertia ixx="0.000007895" ixy="0" ixz="0.000001300" iyy="0.000009763" iyz="0" izz="0.000002004"/>
    </inertial>
    <collision>
      <origin rpy="0  0  0" xyz="0 0 0"/>
      <geometry>
        <mesh filename="package://strirus_cad_design/stl/collision/leg_70.stl" scale="1 1 1"/>
      </geometry>
    </collision>
    <visual>
      <origin rpy="0  0  0" xyz="0 0 0"/>
      <geometry>
        <mesh filename="package://strirus_cad_design/stl/visual/leg_70.stl" scale="1 1 1"/>
      </geometry>
      <material name="white"/>
    </visual>
  </link>
  <joint name="leg_right_3_revolute_joint" type="revolute">
    <child link="leg_right_3"/>
    <parent link="body_2_part"/>
    <origin rpy="0       6.28318530718        0.261799387799" xyz="0.254893980876 -0.1594607377  0"/>
    <axis xyz="0 -1  0"/>
    <limit effort="1.5" lower="-1e+5" upper="1e+5" velocity="3.0"/>
    <joint_properties damping="0.0" friction="0.0"/>
  </joint>
  <gazebo reference="leg_right_3">
    <material>Gazebo/Gray</material>
  </gazebo>
  <link name="leg_right_2">
    <inertial>
      <mass value="0.012706347"/>
      <origin rpy="0 0 0" xyz="-0.013348671 0 -0.027584119"/>
      <inertia ixx="0.000007895" ixy="0" ixz="0.000001300" iyy="0.000009763" iyz="0" izz="0.000002004"/>
    </inertial>
    <collision>
      <origin rpy="0  0  0" xyz="0 0 0"/>
      <geometry>
        <mesh filename="package://strirus_cad_design/stl/collision/leg_70.stl" scale="1 1 1"/>
      </geometry>
    </collision>
    <visual>
      <origin rpy="0  0  0" xyz="0 0 0"/>
      <geometry>
        <mesh filename="package://strirus_cad_design/stl/visual/leg_70.stl" scale="1 1 1"/>
      </geometry>
      <material name="white"/>
    </visual>
  </link>
  <joint name="leg_right_2_revolute_joint" type="revolute">
    <child link="leg_right_2"/>
    <parent link="body_1_part"/>
    <origin rpy="0       4.18879020479        -0.261799387799" xyz="0.204106019124 -0.1594607377  0"/>
    <axis xyz="0 -1  0"/>
    <limit effort="1.5" lower="-1e+5" upper="1e+5" velocity="3.0"/>
    <joint_properties damping="0.0" friction="0.0"/>
  </joint>
  <gazebo reference="leg_right_2">
    <material>Gazebo/Gray</material>
  </gazebo>
  <link name="leg_right_1">
    <inertial>
      <mass value="0.012706347"/>
      <origin rpy="0 0 0" xyz="-0.013348671 0 -0.027584119"/>
      <inertia ixx="0.000007895" ixy="0" ixz="0.000001300" iyy="0.000009763" iyz="0" izz="0.000002004"/>
    </inertial>
    <collision>
      <origin rpy="0  0  0" xyz="0 0 0"/>
      <geometry>
        <mesh filename="package://strirus_cad_design/stl/collision/leg_70.stl" scale="1 1 1"/>
      </geometry>
    </collision>
    <visual>
      <origin rpy="0  0  0" xyz="0 0 0"/>
      <geometry>
        <mesh filename="package://strirus_cad_design/stl/visual/leg_70.stl" scale="1 1 1"/>
      </geometry>
      <material name="white"/>
    </visual>
  </link>
  <joint name="leg_right_1_revolute_joint" type="revolute">
    <child link="leg_right_1"/>
    <parent link="body_1_part"/>
    <origin rpy="0       2.09439510239        -0.261799387799" xyz="0.098106019124 -0.1594607377  0"/>
    <axis xyz="0 -1  0"/>
    <limit effort="1.5" lower="-1e+5" upper="1e+5" velocity="3.0"/>
    <joint_properties damping="0.0" friction="0.0"/>
  </joint>
  <gazebo reference="leg_right_1">
    <material>Gazebo/Gray</material>
  </gazebo>
  <link name="leg_right_0">
    <inertial>
      <mass value="0.012706347"/>
      <origin rpy="0 0 0" xyz="-0.013348671 0 -0.027584119"/>
      <inertia ixx="0.000007895" ixy="0" ixz="0.000001300" iyy="0.000009763" iyz="0" izz="0.000002004"/>
    </inertial>
    <collision>
      <origin rpy="0  0  0" xyz="0 0 0"/>
      <geometry>
        <mesh filename="package://strirus_cad_design/stl/collision/leg_70.stl" scale="1 1 1"/>
      </geometry>
    </collision>
    <visual>
      <origin rpy="0  0  0" xyz="0 0 0"/>
      <geometry>
        <mesh filename="package://strirus_cad_design/stl/visual/leg_70.stl" scale="1 1 1"/>
      </geometry>
      <material name="white"/>
    </visual>
  </link>
  <joint name="leg_right_0_revolute_joint" type="revolute">
    <child link="leg_right_0"/>
    <parent link="body_1_part"/>
    <origin rpy="0       0.0        -0.261799387799" xyz="-0.007893980876 -0.1594607377  0"/>
    <axis xyz="0 -1  0"/>
    <limit effort="1.5" lower="-1e+5" upper="1e+5" velocity="3.0"/>
    <joint_properties damping="0.0" friction="0.0"/>
  </joint>
  <gazebo reference="leg_right_0">
    <material>Gazebo/Gray</material>
  </gazebo>
  <!-- plugins -->
  <!-- <gazebo>
    <plugin name="gazebo_ros_control" filename="libgazebo_ros_control.so" >
      <robotNamespace></robotNamespace>
    </plugin>
  </gazebo> -->
  <gazebo reference="tof_camera_1">
    <plugin filename="libgazebo_ros_openni_kinect.so" name="camera_plugin">
      <baseline>0.2</baseline>
      <alwaysOn>true</alwaysOn>
      <!-- Keep this zero, update_rate in the parent <sensor> tag
        will control the frame rate. -->
      <updateRate>0.0</updateRate>
      <cameraName>tof_camera_1</cameraName>
      <imageTopicName>/camera1/color/image_raw</imageTopicName>
      <cameraInfoTopicName>/camera1/color/camera_info</cameraInfoTopicName>
      <depthImageTopicName>/camera1/depth/image_raw</depthImageTopicName>
      <depthImageCameraInfoTopicName>/camera1/depth/camera_info</depthImageCameraInfoTopicName>
      <pointCloudTopicName>/camera1/depth/points</pointCloudTopicName>
      <frameName>camera_link_1</frameName>
      <pointCloudCutoff>0.5</pointCloudCutoff>
      <pointCloudCutoffMax>3.0</pointCloudCutoffMax>
      <distortionK1>0</distortionK1>
      <distortionK2>0</distortionK2>
      <distortionK3>0</distortionK3>
      <distortionT1>0</distortionT1>
      <distortionT2>0</distortionT2>
      <CxPrime>0</CxPrime>
      <Cx>0</Cx>
      <Cy>0</Cy>
      <focalLength>0</focalLength>
      <hackBaseline>0</hackBaseline>
    </plugin>
  </gazebo>
  <gazebo reference="tof_camera_2">
    <plugin filename="libgazebo_ros_openni_kinect.so" name="camera_plugin">
      <baseline>0.2</baseline>
      <alwaysOn>true</alwaysOn>
      <!-- Keep this zero, update_rate in the parent <sensor> tag
        will control the frame rate. -->
      <updateRate>0.0</updateRate>
      <cameraName>tof_camera_2</cameraName>
      <imageTopicName>/camera2/color/image_raw</imageTopicName>
      <cameraInfoTopicName>/camera2/color/camera_info</cameraInfoTopicName>
      <depthImageTopicName>/camera2/depth/image_raw</depthImageTopicName>
      <depthImageCameraInfoTopicName>/camera2/depth/camera_info</depthImageCameraInfoTopicName>
      <pointCloudTopicName>/camera2/depth/points</pointCloudTopicName>
      <frameName>camera_link_2</frameName>
      <pointCloudCutoff>0.5</pointCloudCutoff>
      <pointCloudCutoffMax>3.0</pointCloudCutoffMax>
      <distortionK1>0</distortionK1>
      <distortionK2>0</distortionK2>
      <distortionK3>0</distortionK3>
      <distortionT1>0</distortionT1>
      <distortionT2>0</distortionT2>
      <CxPrime>0</CxPrime>
      <Cx>0</Cx>
      <Cy>0</Cy>
      <focalLength>0</focalLength>
      <hackBaseline>0</hackBaseline>
    </plugin>
  </gazebo>
</robot>

